<?xml version="1.0" encoding="UTF-8"?>
<!-- Generated by org.testng.reporters.JUnitReportReporter -->
<testsuite skipped="0" hostname="DESKTOP-LI8NPUC" name="unitTest.CustomerDAOTest" tests="49" failures="7" timestamp="2020-04-09T19:48:55 ICT" time="7.735" errors="0">
  <testcase name="addCustomer" time="0.215" classname="unitTest.CustomerDAOTest"/>
  <testcase name="addCustomer" time="0.092" classname="unitTest.CustomerDAOTest"/>
  <testcase name="addCustomer" time="0.099" classname="unitTest.CustomerDAOTest"/>
  <testcase name="addCustomer" time="0.040" classname="unitTest.CustomerDAOTest"/>
  <testcase name="addCustomer" time="0.114" classname="unitTest.CustomerDAOTest"/>
  <testcase name="addCustomer" time="0.149" classname="unitTest.CustomerDAOTest"/>
  <testcase name="addCustomer" time="0.147" classname="unitTest.CustomerDAOTest"/>
  <testcase name="addCustomer" time="0.102" classname="unitTest.CustomerDAOTest"/>
  <testcase name="addCustomer" time="0.046" classname="unitTest.CustomerDAOTest"/>
  <testcase name="addCustomer" time="0.100" classname="unitTest.CustomerDAOTest"/>
  <testcase name="addCustomer" time="0.128" classname="unitTest.CustomerDAOTest"/>
  <testcase name="addCustomer" time="0.063" classname="unitTest.CustomerDAOTest"/>
  <testcase name="addCustomer" time="0.015" classname="unitTest.CustomerDAOTest"/>
  <testcase name="addCustomer" time="1.268" classname="unitTest.CustomerDAOTest"/>
  <testcase name="addCustomer" time="0.177" classname="unitTest.CustomerDAOTest"/>
  <testcase name="addCustomer" time="0.218" classname="unitTest.CustomerDAOTest"/>
  <testcase name="addCustomer" time="0.306" classname="unitTest.CustomerDAOTest"/>
  <testcase name="addCustomer" time="0.125" classname="unitTest.CustomerDAOTest"/>
  <testcase name="addCustomer" time="0.171" classname="unitTest.CustomerDAOTest"/>
  <testcase name="addCustomer" time="0.228" classname="unitTest.CustomerDAOTest">
    <failure type="java.lang.AssertionError" message="expected [false] but found [true]">
      <![CDATA[java.lang.AssertionError: expected [false] but found [true]
at org.testng.Assert.fail(Assert.java:97)
at org.testng.Assert.assertEqualsImpl(Assert.java:136)
at org.testng.Assert.assertEquals(Assert.java:118)
at org.testng.Assert.assertEquals(Assert.java:563)
at unitTest.CustomerDAOTest.addCustomer(CustomerDAOTest.java:54)
at sun.reflect.GeneratedMethodAccessor82.invoke(Unknown Source)
at sun.reflect.DelegatingMethodAccessorImpl.invoke(Unknown Source)
at java.lang.reflect.Method.invoke(Unknown Source)
at org.testng.internal.MethodInvocationHelper.invokeMethod(MethodInvocationHelper.java:133)
at org.testng.internal.MethodInvocationHelper$1.runTestMethod(MethodInvocationHelper.java:239)
at org.springframework.test.context.testng.AbstractTestNGSpringContextTests.run(AbstractTestNGSpringContextTests.java:180)
at org.testng.internal.MethodInvocationHelper.invokeHookable(MethodInvocationHelper.java:251)
at org.testng.internal.TestInvoker.invokeMethod(TestInvoker.java:580)
at org.testng.internal.TestInvoker.invokeTestMethod(TestInvoker.java:172)
at org.testng.internal.MethodRunner.runInSequence(MethodRunner.java:46)
at org.testng.internal.TestInvoker$MethodInvocationAgent.invoke(TestInvoker.java:804)
at org.testng.internal.TestInvoker.invokeTestMethods(TestInvoker.java:145)
at org.testng.internal.TestMethodWorker.invokeTestMethods(TestMethodWorker.java:146)
at org.testng.internal.TestMethodWorker.run(TestMethodWorker.java:128)
at java.util.ArrayList.forEach(Unknown Source)
at org.testng.TestRunner.privateRun(TestRunner.java:770)
at org.testng.TestRunner.run(TestRunner.java:591)
at org.testng.SuiteRunner.runTest(SuiteRunner.java:402)
at org.testng.SuiteRunner.runSequentially(SuiteRunner.java:396)
at org.testng.SuiteRunner.privateRun(SuiteRunner.java:355)
at org.testng.SuiteRunner.run(SuiteRunner.java:304)
at org.testng.SuiteRunnerWorker.runSuite(SuiteRunnerWorker.java:53)
at org.testng.SuiteRunnerWorker.run(SuiteRunnerWorker.java:96)
at org.testng.TestNG.runSuitesSequentially(TestNG.java:1180)
at org.testng.TestNG.runSuitesLocally(TestNG.java:1102)
at org.testng.TestNG.runSuites(TestNG.java:1032)
at org.testng.TestNG.run(TestNG.java:1000)
at org.testng.remote.AbstractRemoteTestNG.run(AbstractRemoteTestNG.java:115)
at org.testng.remote.RemoteTestNG.initAndRun(RemoteTestNG.java:251)
at org.testng.remote.RemoteTestNG.main(RemoteTestNG.java:77)
]]>
    </failure>
  </testcase> <!-- addCustomer -->
  <testcase name="addCustomer" time="0.108" classname="unitTest.CustomerDAOTest"/>
  <testcase name="addCustomer" time="0.199" classname="unitTest.CustomerDAOTest"/>
  <testcase name="addCustomer" time="0.194" classname="unitTest.CustomerDAOTest">
    <failure type="java.lang.AssertionError" message="expected [false] but found [true]">
      <![CDATA[java.lang.AssertionError: expected [false] but found [true]
at org.testng.Assert.fail(Assert.java:97)
at org.testng.Assert.assertEqualsImpl(Assert.java:136)
at org.testng.Assert.assertEquals(Assert.java:118)
at org.testng.Assert.assertEquals(Assert.java:563)
at unitTest.CustomerDAOTest.addCustomer(CustomerDAOTest.java:54)
at sun.reflect.GeneratedMethodAccessor82.invoke(Unknown Source)
at sun.reflect.DelegatingMethodAccessorImpl.invoke(Unknown Source)
at java.lang.reflect.Method.invoke(Unknown Source)
at org.testng.internal.MethodInvocationHelper.invokeMethod(MethodInvocationHelper.java:133)
at org.testng.internal.MethodInvocationHelper$1.runTestMethod(MethodInvocationHelper.java:239)
at org.springframework.test.context.testng.AbstractTestNGSpringContextTests.run(AbstractTestNGSpringContextTests.java:180)
at org.testng.internal.MethodInvocationHelper.invokeHookable(MethodInvocationHelper.java:251)
at org.testng.internal.TestInvoker.invokeMethod(TestInvoker.java:580)
at org.testng.internal.TestInvoker.invokeTestMethod(TestInvoker.java:172)
at org.testng.internal.MethodRunner.runInSequence(MethodRunner.java:46)
at org.testng.internal.TestInvoker$MethodInvocationAgent.invoke(TestInvoker.java:804)
at org.testng.internal.TestInvoker.invokeTestMethods(TestInvoker.java:145)
at org.testng.internal.TestMethodWorker.invokeTestMethods(TestMethodWorker.java:146)
at org.testng.internal.TestMethodWorker.run(TestMethodWorker.java:128)
at java.util.ArrayList.forEach(Unknown Source)
at org.testng.TestRunner.privateRun(TestRunner.java:770)
at org.testng.TestRunner.run(TestRunner.java:591)
at org.testng.SuiteRunner.runTest(SuiteRunner.java:402)
at org.testng.SuiteRunner.runSequentially(SuiteRunner.java:396)
at org.testng.SuiteRunner.privateRun(SuiteRunner.java:355)
at org.testng.SuiteRunner.run(SuiteRunner.java:304)
at org.testng.SuiteRunnerWorker.runSuite(SuiteRunnerWorker.java:53)
at org.testng.SuiteRunnerWorker.run(SuiteRunnerWorker.java:96)
at org.testng.TestNG.runSuitesSequentially(TestNG.java:1180)
at org.testng.TestNG.runSuitesLocally(TestNG.java:1102)
at org.testng.TestNG.runSuites(TestNG.java:1032)
at org.testng.TestNG.run(TestNG.java:1000)
at org.testng.remote.AbstractRemoteTestNG.run(AbstractRemoteTestNG.java:115)
at org.testng.remote.RemoteTestNG.initAndRun(RemoteTestNG.java:251)
at org.testng.remote.RemoteTestNG.main(RemoteTestNG.java:77)
]]>
    </failure>
  </testcase> <!-- addCustomer -->
  <testcase name="addCustomer" time="0.175" classname="unitTest.CustomerDAOTest"/>
  <testcase name="addCustomer" time="0.136" classname="unitTest.CustomerDAOTest"/>
  <testcase name="addCustomer" time="0.246" classname="unitTest.CustomerDAOTest">
    <failure type="java.lang.AssertionError" message="expected [false] but found [true]">
      <![CDATA[java.lang.AssertionError: expected [false] but found [true]
at org.testng.Assert.fail(Assert.java:97)
at org.testng.Assert.assertEqualsImpl(Assert.java:136)
at org.testng.Assert.assertEquals(Assert.java:118)
at org.testng.Assert.assertEquals(Assert.java:563)
at unitTest.CustomerDAOTest.addCustomer(CustomerDAOTest.java:54)
at sun.reflect.NativeMethodAccessorImpl.invoke0(Native Method)
at sun.reflect.NativeMethodAccessorImpl.invoke(Unknown Source)
at sun.reflect.DelegatingMethodAccessorImpl.invoke(Unknown Source)
at java.lang.reflect.Method.invoke(Unknown Source)
at org.testng.internal.MethodInvocationHelper.invokeMethod(MethodInvocationHelper.java:133)
at org.testng.internal.MethodInvocationHelper$1.runTestMethod(MethodInvocationHelper.java:239)
at org.springframework.test.context.testng.AbstractTestNGSpringContextTests.run(AbstractTestNGSpringContextTests.java:180)
at org.testng.internal.MethodInvocationHelper.invokeHookable(MethodInvocationHelper.java:251)
at org.testng.internal.TestInvoker.invokeMethod(TestInvoker.java:580)
at org.testng.internal.TestInvoker.invokeTestMethod(TestInvoker.java:172)
at org.testng.internal.MethodRunner.runInSequence(MethodRunner.java:46)
at org.testng.internal.TestInvoker$MethodInvocationAgent.invoke(TestInvoker.java:804)
at org.testng.internal.TestInvoker.invokeTestMethods(TestInvoker.java:145)
at org.testng.internal.TestMethodWorker.invokeTestMethods(TestMethodWorker.java:146)
at org.testng.internal.TestMethodWorker.run(TestMethodWorker.java:128)
at java.util.ArrayList.forEach(Unknown Source)
at org.testng.TestRunner.privateRun(TestRunner.java:770)
at org.testng.TestRunner.run(TestRunner.java:591)
at org.testng.SuiteRunner.runTest(SuiteRunner.java:402)
at org.testng.SuiteRunner.runSequentially(SuiteRunner.java:396)
at org.testng.SuiteRunner.privateRun(SuiteRunner.java:355)
at org.testng.SuiteRunner.run(SuiteRunner.java:304)
at org.testng.SuiteRunnerWorker.runSuite(SuiteRunnerWorker.java:53)
at org.testng.SuiteRunnerWorker.run(SuiteRunnerWorker.java:96)
at org.testng.TestNG.runSuitesSequentially(TestNG.java:1180)
at org.testng.TestNG.runSuitesLocally(TestNG.java:1102)
at org.testng.TestNG.runSuites(TestNG.java:1032)
at org.testng.TestNG.run(TestNG.java:1000)
at org.testng.remote.AbstractRemoteTestNG.run(AbstractRemoteTestNG.java:115)
at org.testng.remote.RemoteTestNG.initAndRun(RemoteTestNG.java:251)
at org.testng.remote.RemoteTestNG.main(RemoteTestNG.java:77)
]]>
    </failure>
  </testcase> <!-- addCustomer -->
  <testcase name="addCustomer" time="0.250" classname="unitTest.CustomerDAOTest"/>
  <testcase name="addCustomer" time="0.011" classname="unitTest.CustomerDAOTest"/>
  <testcase name="addCustomer" time="0.058" classname="unitTest.CustomerDAOTest"/>
  <testcase name="addCustomer" time="0.069" classname="unitTest.CustomerDAOTest">
    <failure type="java.lang.AssertionError" message="expected [false] but found [true]">
      <![CDATA[java.lang.AssertionError: expected [false] but found [true]
at org.testng.Assert.fail(Assert.java:97)
at org.testng.Assert.assertEqualsImpl(Assert.java:136)
at org.testng.Assert.assertEquals(Assert.java:118)
at org.testng.Assert.assertEquals(Assert.java:563)
at unitTest.CustomerDAOTest.addCustomer(CustomerDAOTest.java:54)
at sun.reflect.GeneratedMethodAccessor82.invoke(Unknown Source)
at sun.reflect.DelegatingMethodAccessorImpl.invoke(Unknown Source)
at java.lang.reflect.Method.invoke(Unknown Source)
at org.testng.internal.MethodInvocationHelper.invokeMethod(MethodInvocationHelper.java:133)
at org.testng.internal.MethodInvocationHelper$1.runTestMethod(MethodInvocationHelper.java:239)
at org.springframework.test.context.testng.AbstractTestNGSpringContextTests.run(AbstractTestNGSpringContextTests.java:180)
at org.testng.internal.MethodInvocationHelper.invokeHookable(MethodInvocationHelper.java:251)
at org.testng.internal.TestInvoker.invokeMethod(TestInvoker.java:580)
at org.testng.internal.TestInvoker.invokeTestMethod(TestInvoker.java:172)
at org.testng.internal.MethodRunner.runInSequence(MethodRunner.java:46)
at org.testng.internal.TestInvoker$MethodInvocationAgent.invoke(TestInvoker.java:804)
at org.testng.internal.TestInvoker.invokeTestMethods(TestInvoker.java:145)
at org.testng.internal.TestMethodWorker.invokeTestMethods(TestMethodWorker.java:146)
at org.testng.internal.TestMethodWorker.run(TestMethodWorker.java:128)
at java.util.ArrayList.forEach(Unknown Source)
at org.testng.TestRunner.privateRun(TestRunner.java:770)
at org.testng.TestRunner.run(TestRunner.java:591)
at org.testng.SuiteRunner.runTest(SuiteRunner.java:402)
at org.testng.SuiteRunner.runSequentially(SuiteRunner.java:396)
at org.testng.SuiteRunner.privateRun(SuiteRunner.java:355)
at org.testng.SuiteRunner.run(SuiteRunner.java:304)
at org.testng.SuiteRunnerWorker.runSuite(SuiteRunnerWorker.java:53)
at org.testng.SuiteRunnerWorker.run(SuiteRunnerWorker.java:96)
at org.testng.TestNG.runSuitesSequentially(TestNG.java:1180)
at org.testng.TestNG.runSuitesLocally(TestNG.java:1102)
at org.testng.TestNG.runSuites(TestNG.java:1032)
at org.testng.TestNG.run(TestNG.java:1000)
at org.testng.remote.AbstractRemoteTestNG.run(AbstractRemoteTestNG.java:115)
at org.testng.remote.RemoteTestNG.initAndRun(RemoteTestNG.java:251)
at org.testng.remote.RemoteTestNG.main(RemoteTestNG.java:77)
]]>
    </failure>
  </testcase> <!-- addCustomer -->
  <testcase name="addCustomer" time="0.042" classname="unitTest.CustomerDAOTest"/>
  <testcase name="addCustomer" time="0.072" classname="unitTest.CustomerDAOTest"/>
  <testcase name="addCustomer" time="0.092" classname="unitTest.CustomerDAOTest"/>
  <testcase name="addCustomer" time="0.029" classname="unitTest.CustomerDAOTest"/>
  <testcase name="addCustomer" time="0.294" classname="unitTest.CustomerDAOTest"/>
  <testcase name="addCustomer" time="0.084" classname="unitTest.CustomerDAOTest"/>
  <testcase name="addCustomer" time="0.221" classname="unitTest.CustomerDAOTest"/>
  <testcase name="addCustomer" time="0.181" classname="unitTest.CustomerDAOTest">
    <failure type="java.lang.AssertionError" message="expected [false] but found [true]">
      <![CDATA[java.lang.AssertionError: expected [false] but found [true]
at org.testng.Assert.fail(Assert.java:97)
at org.testng.Assert.assertEqualsImpl(Assert.java:136)
at org.testng.Assert.assertEquals(Assert.java:118)
at org.testng.Assert.assertEquals(Assert.java:563)
at unitTest.CustomerDAOTest.addCustomer(CustomerDAOTest.java:54)
at sun.reflect.NativeMethodAccessorImpl.invoke0(Native Method)
at sun.reflect.NativeMethodAccessorImpl.invoke(Unknown Source)
at sun.reflect.DelegatingMethodAccessorImpl.invoke(Unknown Source)
at java.lang.reflect.Method.invoke(Unknown Source)
at org.testng.internal.MethodInvocationHelper.invokeMethod(MethodInvocationHelper.java:133)
at org.testng.internal.MethodInvocationHelper$1.runTestMethod(MethodInvocationHelper.java:239)
at org.springframework.test.context.testng.AbstractTestNGSpringContextTests.run(AbstractTestNGSpringContextTests.java:180)
at org.testng.internal.MethodInvocationHelper.invokeHookable(MethodInvocationHelper.java:251)
at org.testng.internal.TestInvoker.invokeMethod(TestInvoker.java:580)
at org.testng.internal.TestInvoker.invokeTestMethod(TestInvoker.java:172)
at org.testng.internal.MethodRunner.runInSequence(MethodRunner.java:46)
at org.testng.internal.TestInvoker$MethodInvocationAgent.invoke(TestInvoker.java:804)
at org.testng.internal.TestInvoker.invokeTestMethods(TestInvoker.java:145)
at org.testng.internal.TestMethodWorker.invokeTestMethods(TestMethodWorker.java:146)
at org.testng.internal.TestMethodWorker.run(TestMethodWorker.java:128)
at java.util.ArrayList.forEach(Unknown Source)
at org.testng.TestRunner.privateRun(TestRunner.java:770)
at org.testng.TestRunner.run(TestRunner.java:591)
at org.testng.SuiteRunner.runTest(SuiteRunner.java:402)
at org.testng.SuiteRunner.runSequentially(SuiteRunner.java:396)
at org.testng.SuiteRunner.privateRun(SuiteRunner.java:355)
at org.testng.SuiteRunner.run(SuiteRunner.java:304)
at org.testng.SuiteRunnerWorker.runSuite(SuiteRunnerWorker.java:53)
at org.testng.SuiteRunnerWorker.run(SuiteRunnerWorker.java:96)
at org.testng.TestNG.runSuitesSequentially(TestNG.java:1180)
at org.testng.TestNG.runSuitesLocally(TestNG.java:1102)
at org.testng.TestNG.runSuites(TestNG.java:1032)
at org.testng.TestNG.run(TestNG.java:1000)
at org.testng.remote.AbstractRemoteTestNG.run(AbstractRemoteTestNG.java:115)
at org.testng.remote.RemoteTestNG.initAndRun(RemoteTestNG.java:251)
at org.testng.remote.RemoteTestNG.main(RemoteTestNG.java:77)
]]>
    </failure>
  </testcase> <!-- addCustomer -->
  <testcase name="addCustomer" time="0.039" classname="unitTest.CustomerDAOTest"/>
  <testcase name="addCustomer" time="0.074" classname="unitTest.CustomerDAOTest"/>
  <testcase name="addCustomer" time="0.341" classname="unitTest.CustomerDAOTest">
    <failure type="java.lang.AssertionError" message="expected [false] but found [true]">
      <![CDATA[java.lang.AssertionError: expected [false] but found [true]
at org.testng.Assert.fail(Assert.java:97)
at org.testng.Assert.assertEqualsImpl(Assert.java:136)
at org.testng.Assert.assertEquals(Assert.java:118)
at org.testng.Assert.assertEquals(Assert.java:563)
at unitTest.CustomerDAOTest.addCustomer(CustomerDAOTest.java:54)
at sun.reflect.GeneratedMethodAccessor82.invoke(Unknown Source)
at sun.reflect.DelegatingMethodAccessorImpl.invoke(Unknown Source)
at java.lang.reflect.Method.invoke(Unknown Source)
at org.testng.internal.MethodInvocationHelper.invokeMethod(MethodInvocationHelper.java:133)
at org.testng.internal.MethodInvocationHelper$1.runTestMethod(MethodInvocationHelper.java:239)
at org.springframework.test.context.testng.AbstractTestNGSpringContextTests.run(AbstractTestNGSpringContextTests.java:180)
at org.testng.internal.MethodInvocationHelper.invokeHookable(MethodInvocationHelper.java:251)
at org.testng.internal.TestInvoker.invokeMethod(TestInvoker.java:580)
at org.testng.internal.TestInvoker.invokeTestMethod(TestInvoker.java:172)
at org.testng.internal.MethodRunner.runInSequence(MethodRunner.java:46)
at org.testng.internal.TestInvoker$MethodInvocationAgent.invoke(TestInvoker.java:804)
at org.testng.internal.TestInvoker.invokeTestMethods(TestInvoker.java:145)
at org.testng.internal.TestMethodWorker.invokeTestMethods(TestMethodWorker.java:146)
at org.testng.internal.TestMethodWorker.run(TestMethodWorker.java:128)
at java.util.ArrayList.forEach(Unknown Source)
at org.testng.TestRunner.privateRun(TestRunner.java:770)
at org.testng.TestRunner.run(TestRunner.java:591)
at org.testng.SuiteRunner.runTest(SuiteRunner.java:402)
at org.testng.SuiteRunner.runSequentially(SuiteRunner.java:396)
at org.testng.SuiteRunner.privateRun(SuiteRunner.java:355)
at org.testng.SuiteRunner.run(SuiteRunner.java:304)
at org.testng.SuiteRunnerWorker.runSuite(SuiteRunnerWorker.java:53)
at org.testng.SuiteRunnerWorker.run(SuiteRunnerWorker.java:96)
at org.testng.TestNG.runSuitesSequentially(TestNG.java:1180)
at org.testng.TestNG.runSuitesLocally(TestNG.java:1102)
at org.testng.TestNG.runSuites(TestNG.java:1032)
at org.testng.TestNG.run(TestNG.java:1000)
at org.testng.remote.AbstractRemoteTestNG.run(AbstractRemoteTestNG.java:115)
at org.testng.remote.RemoteTestNG.initAndRun(RemoteTestNG.java:251)
at org.testng.remote.RemoteTestNG.main(RemoteTestNG.java:77)
]]>
    </failure>
  </testcase> <!-- addCustomer -->
  <testcase name="addCustomer" time="0.120" classname="unitTest.CustomerDAOTest"/>
  <testcase name="addCustomer" time="0.198" classname="unitTest.CustomerDAOTest"/>
  <testcase name="addCustomer" time="0.241" classname="unitTest.CustomerDAOTest">
    <failure type="java.lang.AssertionError" message="expected [false] but found [true]">
      <![CDATA[java.lang.AssertionError: expected [false] but found [true]
at org.testng.Assert.fail(Assert.java:97)
at org.testng.Assert.assertEqualsImpl(Assert.java:136)
at org.testng.Assert.assertEquals(Assert.java:118)
at org.testng.Assert.assertEquals(Assert.java:563)
at unitTest.CustomerDAOTest.addCustomer(CustomerDAOTest.java:54)
at sun.reflect.NativeMethodAccessorImpl.invoke0(Native Method)
at sun.reflect.NativeMethodAccessorImpl.invoke(Unknown Source)
at sun.reflect.DelegatingMethodAccessorImpl.invoke(Unknown Source)
at java.lang.reflect.Method.invoke(Unknown Source)
at org.testng.internal.MethodInvocationHelper.invokeMethod(MethodInvocationHelper.java:133)
at org.testng.internal.MethodInvocationHelper$1.runTestMethod(MethodInvocationHelper.java:239)
at org.springframework.test.context.testng.AbstractTestNGSpringContextTests.run(AbstractTestNGSpringContextTests.java:180)
at org.testng.internal.MethodInvocationHelper.invokeHookable(MethodInvocationHelper.java:251)
at org.testng.internal.TestInvoker.invokeMethod(TestInvoker.java:580)
at org.testng.internal.TestInvoker.invokeTestMethod(TestInvoker.java:172)
at org.testng.internal.MethodRunner.runInSequence(MethodRunner.java:46)
at org.testng.internal.TestInvoker$MethodInvocationAgent.invoke(TestInvoker.java:804)
at org.testng.internal.TestInvoker.invokeTestMethods(TestInvoker.java:145)
at org.testng.internal.TestMethodWorker.invokeTestMethods(TestMethodWorker.java:146)
at org.testng.internal.TestMethodWorker.run(TestMethodWorker.java:128)
at java.util.ArrayList.forEach(Unknown Source)
at org.testng.TestRunner.privateRun(TestRunner.java:770)
at org.testng.TestRunner.run(TestRunner.java:591)
at org.testng.SuiteRunner.runTest(SuiteRunner.java:402)
at org.testng.SuiteRunner.runSequentially(SuiteRunner.java:396)
at org.testng.SuiteRunner.privateRun(SuiteRunner.java:355)
at org.testng.SuiteRunner.run(SuiteRunner.java:304)
at org.testng.SuiteRunnerWorker.runSuite(SuiteRunnerWorker.java:53)
at org.testng.SuiteRunnerWorker.run(SuiteRunnerWorker.java:96)
at org.testng.TestNG.runSuitesSequentially(TestNG.java:1180)
at org.testng.TestNG.runSuitesLocally(TestNG.java:1102)
at org.testng.TestNG.runSuites(TestNG.java:1032)
at org.testng.TestNG.run(TestNG.java:1000)
at org.testng.remote.AbstractRemoteTestNG.run(AbstractRemoteTestNG.java:115)
at org.testng.remote.RemoteTestNG.initAndRun(RemoteTestNG.java:251)
at org.testng.remote.RemoteTestNG.main(RemoteTestNG.java:77)
]]>
    </failure>
  </testcase> <!-- addCustomer -->
  <testcase name="addCustomer" time="0.041" classname="unitTest.CustomerDAOTest"/>
  <testcase name="addCustomer" time="0.097" classname="unitTest.CustomerDAOTest"/>
  <testcase name="addCustomer" time="0.150" classname="unitTest.CustomerDAOTest"/>
  <testcase name="addCustomer" time="0.037" classname="unitTest.CustomerDAOTest"/>
  <testcase name="addCustomer" time="0.133" classname="unitTest.CustomerDAOTest"/>
</testsuite> <!-- unitTest.CustomerDAOTest -->
